Workbook

Sheet Radicals
A1: No. | B1: Radical | C1: Variant forms | D1: Strokes | E1: Name (kana) | F1: Name (romaji) | G1: Meaning | H1: Group | I1: Kanji count (of 2501) | J1: Kanji using this radical (by frequency rank)
A2: 1 | B2: 一 | D2: 1 | E2: いち | F2: ichi | G2: one | H2: Strokes & numbers | I2: =COUNTIF(Kanji!$C$2:$C$2502,A2) -> 15 | J2: 一三上下不七世両与万並丁丈丘丑
A3: 2 | B3: 丨 | D3: 1 | E3: たてぼう | F3: tatebou | G3: vertical line | H3: Strokes & numbers | I3: =COUNTIF(Kanji!$C$2:$C$2502,A3) -> 2 | J3: 中串
A4: 3 | B4: 丶 | D4: 1 | E4: てん | F4: ten | G4: dot | H4: Strokes & numbers | I4: =COUNTIF(Kanji!$C$2:$C$2502,A4) -> 4 | J4: 主丸丹丼
A5: 4 | B5: 丿 | D5: 1 | E5: の / はらいぼう | F5: no / haraibou | G5: slash, left-falling stroke | H5: Strokes & numbers | I5: =COUNTIF(Kanji!$C$2:$C$2502,A5) -> 5 | J5: 乗久之乏乃
A6: 5 | B6: 乙 | C6: 乚 | D6: 1 | E6: おつ / おっ | F6: otsu / o | G6: second, hook | H6: Strokes & numbers | I6: =COUNTIF(Kanji!$C$2:$C$2502,A6) -> 8 | J6: 九乱乳亀也乾乙乞
A7: 6 | B7: 亅 | D7: 1 | E7: はねぼう | F7: hanebou | G7: hook, barb | H7: Strokes & numbers | I7: =COUNTIF(Kanji!$C$2:$C$2502,A7) -> 4 | J7: 事予争了
A8: 7 | B8: 二 | D8: 2 | E8: に | F8: ni | G8: two | H8: Strokes & numbers | I8: =COUNTIF(Kanji!$C$2:$C$2502,A8) -> 6 | J8: 二五井互亜亘
A9: 8 | B9: 亠 | D9: 2 | E9: なべぶた / けいさんかんむり | F9: nabebuta / keisankanmuri | G9: lid, top | H9: Buildings, covers & enclosures | I9: =COUNTIF(Kanji!$C$2:$C$2502,A9) -> 7 | J9: 京交亡亭亮享亨
A10: 9 | B10: 人 | C10: 亻・⺅ (にんべん, left side); 𠆢 (ひとやね / ひとがしら, top) | D10: 2 | E10: ひと | F10: hito | G10: person | H10: Person & family | I10: =COUNTIF(Kanji!$C$2:$C$2502,A10) -> 112 | J10: 会人今代体作以保信件側任使係価住位企供付優何備例伝働低仕個佐候値催他健修介休余伊僚倍億債便伸停儀倒令仏傷償像伴依仲似借傾併促俊侵仮倉俳仙舎偽僕倫仁偏舗俵仰俣偶伏俗偉佳傍傘僧伯伐俸倶偵伍傑侍俺侮僑倭儒佃伺佑仇伽偲侯侠但儲倣偕倹
A11: 10 | B11: 儿 | D11: 2 | E11: ひとあし / にんにょう | F11: hitoashi / ninnyou | G11: legs, walking person | H11: Person & family | I11: =COUNTIF(Kanji!$C$2:$C$2502,A11) -> 12 | J11: 党先元光児充免兆兄克兜允
A12: 11 | B12: 入 | C12: ⺊ (いりがしら, top form) | D12: 2 | E12: いる | F12: iru | G12: enter | H12: Actions & movement | I12: =COUNTIF(Kanji!$C$2:$C$2502,A12) -> 2 | J12: 入全
A13: 12 | B13: 八 | C13: 丷 (はちがしら, top form) | D13: 2 | E13: はち | F13: hachi | G13: eight | H13: Strokes & numbers | I13: =COUNTIF(Kanji!$C$2:$C$2502,A13) -> 10 | J13: 八六公共兵具典兼曽其
A14: 13 | B14: 冂 | D14: 2 | E14: まきがまえ / えんがまえ / どうがまえ | F14: makigamae / engamae / dougamae | G14: down box, upside-down box | H14: Buildings, covers & enclosures | I14: =COUNTIF(Kanji!$C$2:$C$2502,A14) -> 5 | J14: 内円再冊冒
A15: 14 | B15: 冖 | D15: 2 | E15: わかんむり | F15: wakanmuri | G15: cover, crown | H15: Buildings, covers & enclosures | I15: =COUNTIF(Kanji!$C$2:$C$2502,A15) -> 6 | J15: 写冠冗冨冥冤
A16: 15 | B16: 冫 | D16: 2 | E16: にすい | F16: nisui | G16: ice | H16: Water, fire, earth & land | I16: =COUNTIF(Kanji!$C$2:$C$2502,A16) -> 8 | J16: 冷冬凍准凝凄冴凌
A17: 16 | B17: 几 | D17: 2 | E17: つくえ / きにょう | F17: tsukue / kinyou | G17: table, wind | H17: Tools, weapons & objects | I17: =COUNTIF(Kanji!$C$2:$C$2502,A17) -> 4 | J17: 処凡凧凱
A18: 17 | B18: 凵 | D18: 2 | E18: うけばこ | F18: ukebako | G18: open box | H18: Buildings, covers & enclosures | I18: =COUNTIF(Kanji!$C$2:$C$2502,A18) -> 5 | J18: 出凶函凸凹
A19: 18 | B19: 刀 | C19: 刂 (りっとう, right side); ⺈ | D19: 2 | E19: かたな | F19: katana | G19: knife, sword | H19: Tools, weapons & objects | I19: =COUNTIF(Kanji!$C$2:$C$2502,A19) -> 33 | J19: 分前制初判利別割切副券劇創則削刊刑刻列刺到剤剣刷剰剛刈刃刀剖劉剥剃
A20: 19 | B20: 力 | D20: 2 | E20: ちから | F20: chikara | G20: power, strength | H20: Actions & movement | I20: =COUNTIF(Kanji!$C$2:$C$2502,A20) -> 22 | J20: 力動務加勝勢助労効努募勤功勉勧励勇勘勲劣劾勅
A21: 20 | B21: 勹 | D21: 2 | E21: つつみがまえ | F21: tsutsumigamae | G21: wrap | H21: Buildings, covers & enclosures | I21: =COUNTIF(Kanji!$C$2:$C$2502,A21) -> 2 | J21: 包匂
A22: 21 | B22: 匕 | D22: 2 | E22: さじ / ひ | F22: saji / hi | G22: spoon, ladle | H22: Tools, weapons & objects | I22: =COUNTIF(Kanji!$C$2:$C$2502,A22) -> 2 | J22: 化北
A23: 22 | B23: 匚 | D23: 2 | E23: はこがまえ | F23: hakogamae | G23: box (open right) | H23: Buildings, covers & enclosures | I23: =COUNTIF(Kanji!$C$2:$C$2502,A23) -> 2 | J23: 匠匡
A24: 23 | B24: 匸 | D24: 2 | E24: かくしがまえ | F24: kakushigamae | G24: hiding enclosure | H24: Buildings, covers & enclosures | I24: =COUNTIF(Kanji!$C$2:$C$2502,A24) -> 4 | J24: 区医匹匿
A25: 24 | B25: 十 | D25: 2 | E25: じゅう | F25: juu | G25: ten | H25: Strokes & numbers | I25: =COUNTIF(Kanji!$C$2:$C$2502,A25) -> 12 | J25: 十協午千半南単卒博卓卑升
A26: 25 | B26: 卜 | D26: 2 | E26: ぼく / うらない | F26: boku / uranai | G26: divination | H26: Actions & movement | I26: =COUNTIF(Kanji!$C$2:$C$2502,A26) -> 1 | J26: 占
A27: 26 | B27: 卩 | C27: 㔾 | D27: 2 | E27: ふしづくり / わりふ | F27: fushizukuri / warifu | G27: seal, kneeling person | H27: Actions & movement | I27: =COUNTIF(Kanji!$C$2:$C$2502,A27) -> 8 | J27: 危印却即卵卸卿卯
A28: 27 | B28: 厂 | D28: 2 | E28: がんだれ | F28: gandare | G28: cliff | H28: Water, fire, earth & land | I28: =COUNTIF(Kanji!$C$2:$C$2502,A28) -> 7 | J28: 原厳厚厘厄厦厨
A29: 28 | B29: 厶 | D29: 2 | E29: む | F29: mu | G29: private | H29: Other & abstract | I29: =COUNTIF(Kanji!$C$2:$C$2502,A29) -> 2 | J29: 参去
A30: 29 | B30: 又 | D30: 2 | E30: また | F30: mata | G30: again, right hand | H30: Body parts & health | I30: =COUNTIF(Kanji!$C$2:$C$2502,A30) -> 11 | J30: 取受反収及友双又叔叙叢
A31: 30 | B31: 口 | D31: 3 | E31: くち | F31: kuchi | G31: mouth | H31: Body parts & health | I31: =COUNTIF(Kanji!$C$2:$C$2502,A31) -> 87 | J31: 同合員問和名向告品各台口営可商味命含呼古史器否周号右吉司善喜喪君吸哲喚唱吹句噴唆唯喫啓叫咲召嘉呈后嘆吐哀唐呉吾呆喝嘱吟喬唇哨唄呂呪嚇嘘喧叱囃只噂噺嗣叶叩咸呑喉噛喋喘哺啄嗜吊嗅
A32: 31 | B32: 囗 | D32: 3 | E32: くにがまえ | F32: kunigamae | G32: enclosure | H32: Buildings, covers & enclosures | I32: =COUNTIF(Kanji!$C$2:$C$2502,A32) -> 12 | J32: 国四回団図園因固囲困圏囚
A33: 32 | B33: 土 | D33: 3 | E33: つち | F33: tsuchi | G33: earth, soil | H33: Water, fire, earth & land | I33: =COUNTIF(Kanji!$C$2:$C$2502,A33) -> 54 | J33: 地場報在増基土境域型塁均圧壊城執坂塚埼堂壁堅埋塩堀塾墓壌塗培墜壇垣墨堤塔垂塊墳坪坊圭堺堰堪塀坑堕尭埴堆壕坐塙
A34: 33 | B34: 士 | D34: 3 | E34: さむらい | F34: samurai | G34: scholar, samurai | H34: Person & family | I34: =COUNTIF(Kanji!$C$2:$C$2502,A34) -> 7 | J34: 売声士壮壷壱壬
A35: 34 | B35: 夂 | D35: 3 | E35: ふゆがしら / ちかんむり | F35: fuyugashira / chikanmuri | G35: go | H35: Actions & movement | I35: =COUNTIF(Kanji!$C$2:$C$2502,A35) -> 1 | J35: 変
A36: 35 | B36: 夊 | D36: 3 | E36: すいにょう | F36: suinyou | G36: go slowly | H36: Actions & movement | I36: =COUNTIF(Kanji!$C$2:$C$2502,A36) -> 1 | J36: 夏
A37: 36 | B37: 夕 | D37: 3 | E37: ゆう / ゆうべ | F37: yuu / yuube | G37: evening | H37: Sky, time & weather | I37: =COUNTIF(Kanji!$C$2:$C$2502,A37) -> 5 | J37: 外多夜夕夢
A38: 37 | B38: 大 | D38: 3 | E38: だい | F38: dai | G38: big | H38: Person & family | I38: =COUNTIF(Kanji!$C$2:$C$2502,A38) -> 18 | J38: 大夫失天太央奈契奪奥奏奇奨奮奉奔奄夷
A39: 38 | B39: 女 | D39: 3 | E39: おんな | F39: onna | G39: woman | H39: Person & family | I39: =COUNTIF(Kanji!$C$2:$C$2502,A39) -> 40 | J39: 女委始好姿婦妻婚妥威妙娘嫌妊妹姉妨姫嫁娠姓如媛妃娯媒姜奴妖姻姑嬢婿嫡娼妄嬉嫉姚婆
... A42: 41 | B42: 寸 | D42: 3 | E42: すん | F42: sun | G42: inch | H42: Actions & movement | I42: =COUNTIF(Kanji!$C$2:$C$2502,A42) -> 12 | J42: 対導専将寺射封尊寿尋寸尉
...

Sheet Kanji
A1: Freq rank | B1: Kanji | C1: Radical no. | D1: Radical | E1: Radical meaning | F1: Radical strokes | G1: Kanji strokes
A2: 1 | B2: 日 | C2: 72 | D2: =INDEX(Radicals!$B$2:$B$215,MATCH(C2,Radicals!$A$2:$A$215,0)) -> 日 | E2: =INDEX(Radicals!$G$2:$G$215,MATCH(C2,Radicals!$A$2:$A$215,0)) -> sun, day | F2: =INDEX(Radicals!$D$2:$D$215,MATCH(C2,Radicals!$A$2:$A$215,0)) -> 4 | G2: 4
A3: 2 | B3: 一 | C3: 1 | D3: =INDEX(Radicals!$B$2:$B$215,MATCH(C3,Radicals!$A$2:$A$215,0)) -> 一 | E3: =INDEX(Radicals!$G$2:$G$215,MATCH(C3,Radicals!$A$2:$A$215,0)) -> one | F3: =INDEX(Radicals!$D$2:$D$215,MATCH(C3,Radicals!$A$2:$A$215,0)) -> 1 | G3: 1
A4: 3 | B4: 国 | C4: 31 | D4: =INDEX(Radicals!$B$2:$B$215,MATCH(C4,Radicals!$A$2:$A$215,0)) -> 囗 | E4: =INDEX(Radicals!$G$2:$G$215,MATCH(C4,Radicals!$A$2:$A$215,0)) -> enclosure | F4: =INDEX(Radicals!$D$2:$D$215,MATCH(C4,Radicals!$A$2:$A$215,0)) -> 3 | G4: 8
A5: 4 | B5: 会 | C5: 9 | D5: =INDEX(Radicals!$B$2:$B$215,MATCH(C5,Radicals!$A$2:$A$215,0)) -> 人 | E5: =INDEX(Radicals!$G$2:$G$215,MATCH(C5,Radicals!$A$2:$A$215,0)) -> person | F5: =INDEX(Radicals!$D$2:$D$215,MATCH(C5,Radicals!$A$2:$A$215,0)) -> 2 | G5: 6
A6: 5 | B6: 人 | C6: 9 | D6: =INDEX(Radicals!$B$2:$B$215,MATCH(C6,Radicals!$A$2:$A$215,0)) -> 人 | E6: =INDEX(Radicals!$G$2:$G$215,MATCH(C6,Radicals!$A$2:$A$215,0)) -> person | F6: =INDEX(Radicals!$D$2:$D$215,MATCH(C6,Radicals!$A$2:$A$215,0)) -> 2 | G6: 2
A7: 6 | B7: 年 | C7: 51 | D7: =INDEX(Radicals!$B$2:$B$215,MATCH(C7,Radicals!$A$2:$A$215,0)) -> 干 | E7: =INDEX(Radicals!$G$2:$G$215,MATCH(C7,Radicals!$A$2:$A$215,0)) -> dry, to do with | F7: =INDEX(Radicals!$D$2:$D$215,MATCH(C7,Radicals!$A$2:$A$215,0)) -> 3 | G7: 6
A8: 7 | B8: 大 | C8: 37 | D8: =INDEX(Radicals!$B$2:$B$215,MATCH(C8,Radicals!$A$2:$A$215,0)) -> 大 | E8: =INDEX(Radicals!$G$2:$G$215,MATCH(C8,Radicals!$A$2:$A$215,0)) -> big | F8: =INDEX(Radicals!$D$2:$D$215,MATCH(C8,Radicals!$A$2:$A$215,0)) -> 3 | G8: 3
A9: 8 | B9: 十 | C9: 24 | D9: =INDEX(Radicals!$B$2:$B$215,MATCH(C9,Radicals!$A$2:$A$215,0)) -> 十 | E9: =INDEX(Radicals!$G$2:$G$215,MATCH(C9,Radicals!$A$2:$A$215,0)) -> ten | F9: =INDEX(Radicals!$D$2:$D$215,MATCH(C9,Radicals!$A$2:$A$215,0)) -> 2 | G9: 2
A10: 9 | B10: 二 | C10: 7 | D10: =INDEX(Radicals!$B$2:$B$215,MATCH(C10,Radicals!$A$2:$A$215,0)) -> 二 | E10: =INDEX(Radicals!$G$2:$G$215,MATCH(C10,Radicals!$A$2:$A$215,0)) -> two | F10: =INDEX(Radicals!$D$2:$D$215,MATCH(C10,Radicals!$A$2:$A$215,0)) -> 2 | G10: 2
A11: 10 | B11: 本 | C11: 75 | D11: =INDEX(Radicals!$B$2:$B$215,MATCH(C11,Radicals!$A$2:$A$215,0)) -> 木 | E11: =INDEX(Radicals!$G$2:$G$215,MATCH(C11,Radicals!$A$2:$A$215,0)) -> tree, wood | F11: =INDEX(Radicals!$D$2:$D$215,MATCH(C11,Radicals!$A$2:$A$215,0)) -> 4 | G11: 5
A12: 11 | B12: 中 | C12: 2 | D12: =INDEX(Radicals!$B$2:$B$215,MATCH(C12,Radicals!$A$2:$A$215,0)) -> 丨 | E12: =INDEX(Radicals!$G$2:$G$215,MATCH(C12,Radicals!$A$2:$A$215,0)) -> vertical line | F12: =INDEX(Radicals!$D$2:$D$215,MATCH(C12,Radicals!$A$2:$A$215,0)) -> 1 | G12: 4
A13: 12 | B13: 長 | C13: 168 | D13: =INDEX(Radicals!$B$2:$B$215,MATCH(C13,Radicals!$A$2:$A$215,0)) -> 長 | E13: =INDEX(Radicals!$G$2:$G$215,MATCH(C13,Radicals!$A$2:$A$215,0)) -> long | F13: =INDEX(Radicals!$D$2:$D$215,MATCH(C13,Radicals!$A$2:$A$215,0)) -> 8 | G13: 8
... A2502: 2501 | B2502: 蝦 | C2502: 142 | D2502: =INDEX(Radicals!$B$2:$B$215,MATCH(C2502,Radicals!$A$2:$A$215,0)) -> 虫 | E2502: =INDEX(Radicals!$G$2:$G$215,MATCH(C2502,Radicals!$A$2:$A$215,0)) -> insect | F2502: =INDEX(Radicals!$D$2:$D$215,MATCH(C2502,Radicals!$A$2:$A$215,0)) -> 6 | G2502: 15

Sheet Notes
A1: About this workbook
A2: Kanji set: the 2,501 kanji in Kimtaro's gist 'kanji_by_frequency.txt' (ordered by KANJIDIC2 frequency rank). Source: https://gist.github.com/Kimtaro/50da080ff3cf6202f55a
A3: Radical assignment: the classical (Kangxi) radical number recorded in KANJIDIC2 for each kanji (via the jamdict-data package, compiled 2021). Each kanji is assigned exactly one radical.
A4: Radicals: all 214 Kangxi radicals, ordered by number, which is also stroke-count order. Variant forms (e.g. 亻 for 人, 氵 for 水) are listed in the 'Variant forms' column and counted under the parent radical.
A5: Names, meanings and thematic groups: compiled from standard Kangxi radical references. Groups are my own thematic grouping to cluster similar-meaning radicals, so they are a study aid rather than an official classification.
A6: Some radicals have 0 kanji because no kanji in this 2,501 list is classified under them in KANJIDIC2.
A7: Kanji counts and the radical columns on the Kanji sheet are formulas. The kanji lists on the Radicals sheet are static text generated from the same data.
A8: Note: 𠆢 and ⺅ are component forms of 人, not separate Kangxi radicals. 入 (enter) looks like 人 but is its own radical (No. 11).
